Workbook
Name BEYAZ: #REF!
Name D.DÖKÜM_ATROMİX_24kW: #REF!
Name D.DÖKÜM_NİTROMİX_24kW: #REF!
Name D.DÖKÜM_NİTROMİX_30kW: #REF!
Name DAIKIN: #REF!
Name DAIKIN_CONDANSE_24kW: #REF!
Name DAIKIN_NDJ_24kW: #REF!
Name DAIKIN_NDJ_28kW: #REF!
Name DAIKIN_NDJ_35kW: #REF!
Name DAIKIN_VZ_24kW: #REF!
Name DAIKIN_VZ_30kW: #REF!
Name DAIKIN_VZ_38kW: #REF!
Name DAYLUX_PREMİX_24kW: #REF!
Name İNŞAAT: #REF!
Name KALDE: #REF!
Name KISA_TESİSAT: #REF!
Name KOMPLE: #REF!
Name KROM: #REF!
Name ÖTELEME: #REF!
Name PARKE: #REF!
Name UZUN_TESİSAT: #REF!

Sheet Müşteri için Hesap
B2: Sipariş | C2: Tip | D2: Adet | E2: Fiyat | F2: Toplam Tutar | I2: ÖDEME ŞEKLİ | J2: FİYAT | M2: Concetanate
B3: KOMBİ | C3: AİRFELL_MAESTRO_OPTİMUM_20kW | D3: 1 | E3: =IFERROR(IF(LEN(M3)=0,"",INDEX('Fiyat Listesi ve Açık Hesap'!$C$4:$C$145,MATCH(M3,'Fiyat Listesi ve Açık Hesap'!$D$4:$D$145,0),)),"-") -> 22000 | F3: =IFERROR(IF(LEN(D3)=0,"",E3*D3),"-") -> 22000 | I3: NAKİT | J3: =$F$27*1.2 -> 63564 | M3: =IFERROR(IF(AND(LEN(B3)=0,LEN(C3)=0),"",IF(LEN(C3)=0,B3,B3&"-"&C3)),"") -> KOMBİ-AİRFELL_MAESTRO_OPTİMUM_20kW
B4: KALORİFER TESİSATI | C4: KOMPLE | D4: 1 | E4: =IFERROR(IF(LEN(M4)=0,"",INDEX('Fiyat Listesi ve Açık Hesap'!$C$4:$C$145,MATCH(M4,'Fiyat Listesi ve Açık Hesap'!$D$4:$D$145,0),)),"-") -> 5000 | F4: =IFERROR(IF(LEN(D4)=0,"",E4*D4),"-") -> 5000 | I4: KREDİ KARTI | J4: =J3*1.1 -> 69920.4 | M4: =IFERROR(IF(AND(LEN(B4)=0,LEN(C4)=0),"",IF(LEN(C4)=0,B4,B4&"-"&C4)),"") -> KALORİFER TESİSATI-KOMPLE
B5: DOĞALGAZ TESİSATI | C5: ÇELİK_BORU | D5: 1 | E5: =IFERROR(IF(LEN(M5)=0,"",INDEX('Fiyat Listesi ve Açık Hesap'!$C$4:$C$145,MATCH(M5,'Fiyat Listesi ve Açık Hesap'!$D$4:$D$145,0),)),"-") -> 4000 | F5: =IFERROR(IF(LEN(D5)=0,"",E5*D5),"-") -> 4000 | I5: 12 AY SENET | J5: =J3*1.12 -> 71191.68 | M5: =IFERROR(IF(AND(LEN(B5)=0,LEN(C5)=0),"",IF(LEN(C5)=0,B5,B5&"-"&C5)),"") -> DOĞALGAZ TESİSATI-ÇELİK_BORU
B6: RADYATÖR | C6: WARMHAUS | D6: 5 | E6: =IFERROR(IF(LEN(M6)=0,"",INDEX('Fiyat Listesi ve Açık Hesap'!$C$4:$C$145,MATCH(M6,'Fiyat Listesi ve Açık Hesap'!$D$4:$D$145,0),)),"-") -> 1850 | F6: =IFERROR(IF(LEN(D6)=0,"",E6*D6),"-") -> 9250 | I6: 15 AY SENET | J6: =J3*1.15 -> 73098.6 | M6: =IFERROR(IF(AND(LEN(B6)=0,LEN(C6)=0),"",IF(LEN(C6)=0,B6,B6&"-"&C6)),"") -> RADYATÖR-WARMHAUS
B7: RADYATÖR VANASI | C7: KALDE | D7: 14 | E7: =IFERROR(IF(LEN(M7)=0,"",INDEX('Fiyat Listesi ve Açık Hesap'!$C$4:$C$145,MATCH(M7,'Fiyat Listesi ve Açık Hesap'!$D$4:$D$145,0),)),"-") -> 105 | F7: =IFERROR(IF(LEN(D7)=0,"",E7*D7),"-") -> 1470 | I7: 18 AY SENET | J7: =J3*1.18 -> 75005.52 | M7: =IFERROR(IF(AND(LEN(B7)=0,LEN(C7)=0),"",IF(LEN(C7)=0,B7,B7&"-"&C7)),"") -> RADYATÖR VANASI-KALDE
B8: ODA TERMOSTATI | C8: AİRFELL_KABLOSUZ_TERMOSTAT | D8: 1 | E8: =IFERROR(IF(LEN(M8)=0,"",INDEX('Fiyat Listesi ve Açık Hesap'!$C$4:$C$145,MATCH(M8,'Fiyat Listesi ve Açık Hesap'!$D$4:$D$145,0),)),"-") -> 1000 | F8: =IFERROR(IF(LEN(D8)=0,"",E8*D8),"-") -> 1000 | M8: =IFERROR(IF(AND(LEN(B8)=0,LEN(C8)=0),"",IF(LEN(C8)=0,B8,B8&"-"&C8)),"") -> ODA TERMOSTATI-AİRFELL_KABLOSUZ_TERMOSTAT
B9: KOMBİ DOLABI | C9: VAR | D9: 1 | E9: =IFERROR(IF(LEN(M9)=0,"",INDEX('Fiyat Listesi ve Açık Hesap'!$C$4:$C$145,MATCH(M9,'Fiyat Listesi ve Açık Hesap'!$D$4:$D$145,0),)),"-") -> 1000 | F9: =IFERROR(IF(LEN(D9)=0,"",E9*D9),"-") -> 1000 | M9: =IFERROR(IF(AND(LEN(B9)=0,LEN(C9)=0),"",IF(LEN(C9)=0,B9,B9&"-"&C9)),"") -> KOMBİ DOLABI-VAR
B10: HAVLUPAN | C10: BEYAZ | D10: 1 | E10: =IFERROR(IF(LEN(M10)=0,"",INDEX('Fiyat Listesi ve Açık Hesap'!$C$4:$C$145,MATCH(M10,'Fiyat Listesi ve Açık Hesap'!$D$4:$D$145,0),)),"-") -> 750 | F10: =IFERROR(IF(LEN(D10)=0,"",E10*D10),"-") -> 750 | M10: =IFERROR(IF(AND(LEN(B10)=0,LEN(C10)=0),"",IF(LEN(C10)=0,B10,B10&"-"&C10)),"") -> HAVLUPAN-BEYAZ
B11: BACA UZATMASI | C11: YOK | D11: 1 | E11: =IFERROR(IF(LEN(M11)=0,"",INDEX('Fiyat Listesi ve Açık Hesap'!$C$4:$C$145,MATCH(M11,'Fiyat Listesi ve Açık Hesap'!$D$4:$D$145,0),)),"-") -> - | F11: =IFERROR(IF(LEN(D11)=0,"",E11*D11),"-") -> - | M11: =IFERROR(IF(AND(LEN(B11)=0,LEN(C11)=0),"",IF(LEN(C11)=0,B11,B11&"-"&C11)),"") -> BACA UZATMASI-YOK
B12: BACA DİRSEĞİ | C12: YOK | D12: 1 | E12: =IFERROR(IF(LEN(M12)=0,"",INDEX('Fiyat Listesi ve Açık Hesap'!$C$4:$C$145,MATCH(M12,'Fiyat Listesi ve Açık Hesap'!$D$4:$D$145,0),)),"-") -> 0 | F12: =IFERROR(IF(LEN(D12)=0,"",E12*D12),"-") -> 0 | M12: =IFERROR(IF(AND(LEN(B12)=0,LEN(C12)=0),"",IF(LEN(C12)=0,B12,B12&"-"&C12)),"") -> BACA DİRSEĞİ-YOK
B13: CAM MENFEZ | C13: VAR | D13: 1 | E13: =IFERROR(IF(LEN(M13)=0,"",INDEX('Fiyat Listesi ve Açık Hesap'!$C$4:$C$145,MATCH(M13,'Fiyat Listesi ve Açık Hesap'!$D$4:$D$145,0),)),"-") -> 250 | F13: =IFERROR(IF(LEN(D13)=0,"",E13*D13),"-") -> 250 | M13: =IFERROR(IF(AND(LEN(B13)=0,LEN(C13)=0),"",IF(LEN(C13)=0,B13,B13&"-"&C13)),"") -> CAM MENFEZ-VAR
B14: ELEKTİRİK TESİSATI | C14: VAR | D14: 1 | E14: =IFERROR(IF(LEN(M14)=0,"",INDEX('Fiyat Listesi ve Açık Hesap'!$C$4:$C$145,MATCH(M14,'Fiyat Listesi ve Açık Hesap'!$D$4:$D$145,0),)),"-") -> 250 | F14: =IFERROR(IF(LEN(D14)=0,"",E14*D14),"-") -> 250 | M14: =IFERROR(IF(AND(LEN(B14)=0,LEN(C14)=0),"",IF(LEN(C14)=0,B14,B14&"-"&C14)),"") -> ELEKTİRİK TESİSATI-VAR
B15: İŞÇİLİK | C15: KOMPLE | D15: 1 | E15: =IFERROR(IF(LEN(M15)=0,"",INDEX('Fiyat Listesi ve Açık Hesap'!$C$4:$C$145,MATCH(M15,'Fiyat Listesi ve Açık Hesap'!$D$4:$D$145,0),)),"-") -> 7000 | F15: =IFERROR(IF(LEN(D15)=0,"",E15*D15),"-") -> 7000 | M15: =IFERROR(IF(AND(LEN(B15)=0,LEN(C15)=0),"",IF(LEN(C15)=0,B15,B15&"-"&C15)),"") -> İŞÇİLİK-KOMPLE
B16: FİRMA GİDERİ | C16: VAR | D16: 1 | E16: =IFERROR(IF(LEN(M16)=0,"",INDEX('Fiyat Listesi ve Açık Hesap'!$C$4:$C$145,MATCH(M16,'Fiyat Listesi ve Açık Hesap'!$D$4:$D$145,0),)),"-") -> 1000 | F16: =IFERROR(IF(LEN(D16)=0,"",E16*D16),"-") -> 1000 | M16: =IFERROR(IF(AND(LEN(B16)=0,LEN(C16)=0),"",IF(LEN(C16)=0,B16,B16&"-"&C16)),"") -> FİRMA GİDERİ-VAR
B17: BACA UZATMASI | C17: YOK | D17: 1 | E17: =IFERROR(IF(LEN(M17)=0,"",INDEX('Fiyat Listesi ve Açık Hesap'!$C$4:$C$145,MATCH(M17,'Fiyat Listesi ve Açık Hesap'!$D$4:$D$145,0),)),"-") -> - | F17: =IFERROR(IF(LEN(D17)=0,"",E17*D17),"-") -> - | M17: =IFERROR(IF(AND(LEN(B17)=0,LEN(C17)=0),"",IF(LEN(C17)=0,B17,B17&"-"&C17)),"") -> BACA UZATMASI-YOK
E18: =IFERROR(IF(LEN(M18)=0,"",INDEX('Fiyat Listesi ve Açık Hesap'!$C$4:$C$145,MATCH(M18,'Fiyat Listesi ve Açık Hesap'!$D$4:$D$145,0),)),"-") | F18: =IFERROR(IF(LEN(D18)=0,"",E18*D18),"-") | M18: =IFERROR(IF(AND(LEN(B18)=0,LEN(C18)=0),"",IF(LEN(C18)=0,B18,B18&"-"&C18)),"")
E19: =IFERROR(IF(LEN(M19)=0,"",INDEX('Fiyat Listesi ve Açık Hesap'!$C$4:$C$145,MATCH(M19,'Fiyat Listesi ve Açık Hesap'!$D$4:$D$145,0),)),"-") | F19: =IFERROR(IF(LEN(D19)=0,"",E19*D19),"-") | M19: =IFERROR(IF(AND(LEN(B19)=0,LEN(C19)=0),"",IF(LEN(C19)=0,B19,B19&"-"&C19)),"")
E20: =IFERROR(IF(LEN(M20)=0,"",INDEX('Fiyat Listesi ve Açık Hesap'!$C$4:$C$145,MATCH(M20,'Fiyat Listesi ve Açık Hesap'!$D$4:$D$145,0),)),"-") | F20: =IFERROR(IF(LEN(D20)=0,"",E20*D20),"-") | M20: =IFERROR(IF(AND(LEN(B20)=0,LEN(C20)=0),"",IF(LEN(C20)=0,B20,B20&"-"&C20)),"")
E21: =IFERROR(IF(LEN(M21)=0,"",INDEX('Fiyat Listesi ve Açık Hesap'!$C$4:$C$145,MATCH(M21,'Fiyat Listesi ve Açık Hesap'!$D$4:$D$145,0),)),"-") | F21: =IFERROR(IF(LEN(D21)=0,"",E21*D21),"-") | M21: =IFERROR(IF(AND(LEN(B21)=0,LEN(C21)=0),"",IF(LEN(C21)=0,B21,B21&"-"&C21)),"")
E22: =IFERROR(IF(LEN(M22)=0,"",INDEX('Fiyat Listesi ve Açık Hesap'!$C$4:$C$145,MATCH(M22,'Fiyat Listesi ve Açık Hesap'!$D$4:$D$145,0),)),"-") | F22: =IFERROR(IF(LEN(D22)=0,"",E22*D22),"-") | M22: =IFERROR(IF(AND(LEN(B22)=0,LEN(C22)=0),"",IF(LEN(C22)=0,B22,B22&"-"&C22)),"")
E23: =IFERROR(IF(LEN(M23)=0,"",INDEX('Fiyat Listesi ve Açık Hesap'!$C$4:$C$145,MATCH(M23,'Fiyat Listesi ve Açık Hesap'!$D$4:$D$145,0),)),"-") | F23: =IFERROR(IF(LEN(D23)=0,"",E23*D23),"-") | M23: =IFERROR(IF(AND(LEN(B23)=0,LEN(C23)=0),"",IF(LEN(C23)=0,B23,B23&"-"&C23)),"")
E24: =IFERROR(IF(LEN(M24)=0,"",INDEX('Fiyat Listesi ve Açık Hesap'!$C$4:$C$145,MATCH(M24,'Fiyat Listesi ve Açık Hesap'!$D$4:$D$145,0),)),"-") | F24: =IFERROR(IF(LEN(D24)=0,"",E24*D24),"-") | M24: =IFERROR(IF(AND(LEN(B24)=0,LEN(C24)=0),"",IF(LEN(C24)=0,B24,B24&"-"&C24)),"")
E25: =IFERROR(IF(LEN(M25)=0,"",INDEX('Fiyat Listesi ve Açık Hesap'!$C$4:$C$145,MATCH(M25,'Fiyat Listesi ve Açık Hesap'!$D$4:$D$145,0),)),"-") | F25: =IFERROR(IF(LEN(D25)=0,"",E25*D25),"-") | M25: =IFERROR(IF(AND(LEN(B25)=0,LEN(C25)=0),"",IF(LEN(C25)=0,B25,B25&"-"&C25)),"")
E27: Toplam Tutar | F27: =IFERROR(SUM($F$3:$F$25),"-") -> 52970

Sheet Fiyat Listesi ve Açık Hesap
A2: DATABASE | B2: Sütun1 | C2: Sütun2 | D2: Sütun3 | F2: GENEL TUTAR AÇIK
A3: Ürünler | B3: Tipi | C3: Fiyatlar | D3: Ürünler ve Tipleri | F3: =IFERROR(IF(LEN('Müşteri için Hesap'!B2)=0,"",'Müşteri için Hesap'!B2),"-") -> Sipariş | G3: =IFERROR(IF(LEN('Müşteri için Hesap'!C2)=0,"",'Müşteri için Hesap'!C2),"-") -> Tip | H3: =IFERROR(IF(LEN('Müşteri için Hesap'!D2)=0,"",'Müşteri için Hesap'!D2),"-") -> Adet | I3: =IFERROR(IF(LEN('Müşteri için Hesap'!E2)=0,"",'Müşteri için Hesap'!E2),"-") -> Fiyat | J3: =IFERROR(IF(LEN('Müşteri için Hesap'!F2)=0,"",'Müşteri için Hesap'!F2),"-") -> Toplam Tutar | L3: =IFERROR(IF(LEN('Müşteri için Hesap'!I2)=0,"",'Müşteri için Hesap'!I2),"-") -> ÖDEME ŞEKLİ | M3: =IFERROR(IF(LEN('Müşteri için Hesap'!J2)=0,"",'Müşteri için Hesap'!J2),"-") -> FİYAT | U3: Tip Türleri | V3: Çoğulları Çıkart(Ürünler) | W3: Sabit Sayı | X3: Tip Criteria | Y3: Ürün Criteria | Z3: Countif tip(D.V) | AA3: Countif ürün D.V
A4: BACA DİRSEĞİ | B4: 90 DERECE | C4: 1000 | D4: =IFERROR(IF(AND(LEN(A4)=0,LEN(B4)=0),"",IF(LEN(B4)=0,A4,A4&"-"&B4)),"") -> BACA DİRSEĞİ-90 DERECE | F4: =IFERROR(IF(LEN('Müşteri için Hesap'!B3)=0,"",'Müşteri için Hesap'!B3),"-") -> KOMBİ | G4: =IFERROR(IF(LEN('Müşteri için Hesap'!C3)=0,"",'Müşteri için Hesap'!C3),"-") -> AİRFELL_MAESTRO_OPTİMUM_20kW | H4: =IFERROR(IF(LEN('Müşteri için Hesap'!D3)=0,"",'Müşteri için Hesap'!D3),"-") -> 1 | I4: =IFERROR(IF(LEN('Müşteri için Hesap'!E3)=0,"",'Müşteri için Hesap'!E3),"-") -> 22000 | J4: =IFERROR(IF(LEN('Müşteri için Hesap'!F3)=0,"",'Müşteri için Hesap'!F3),"-") -> 22000 | L4: =IFERROR(IF(LEN('Müşteri için Hesap'!I3)=0,"",'Müşteri için Hesap'!I3),"-") -> NAKİT | M4: =IFERROR(IF(LEN('Müşteri için Hesap'!J3)=0,"",'Müşteri için Hesap'!J3),"-") -> 63564 | U4: {=IFERROR(INDEX($B$4:$B$145, SMALL(IF((LEN($B$4:$B$145)<>0),ROW($B$4:$B$145)-ROW($B$3),"0"),ROW(B4)-ROW($B$3)) ),"0")} -> 90 DERECE | V4: {=IFERROR(INDEX($A$4:$A$145,MATCH(0,COUNTIF($V$3:V3,$A$4:$A$145),0)),"0")} -> BACA DİRSEĞİ | W4: 1 | X4: =U4*W4 -> #VALUE! | Y4: =W4*V4 -> #VALUE! | Z4: =COUNTIF($X$4:$X$198,"<>0") -> 35 | AA4: =COUNTIF($Y$4:$Y$198,"<>0") -> 17
A5: BACA DİRSEĞİ | B5: 45 DERECE | C5: 1000 | D5: =IFERROR(IF(AND(LEN(A5)=0,LEN(B5)=0),"",IF(LEN(B5)=0,A5,A5&"-"&B5)),"") -> BACA DİRSEĞİ-45 DERECE | F5: =IFERROR(IF(LEN('Müşteri için Hesap'!B4)=0,"",'Müşteri için Hesap'!B4),"-") -> KALORİFER TESİSATI | G5: =IFERROR(IF(LEN('Müşteri için Hesap'!C4)=0,"",'Müşteri için Hesap'!C4),"-") -> KOMPLE | H5: =IFERROR(IF(LEN('Müşteri için Hesap'!D4)=0,"",'Müşteri için Hesap'!D4),"-") -> 1 | I5: =IFERROR(IF(LEN('Müşteri için Hesap'!E4)=0,"",'Müşteri için Hesap'!E4),"-") -> 5000 | J5: =IFERROR(IF(LEN('Müşteri için Hesap'!F4)=0,"",'Müşteri için Hesap'!F4),"-") -> 5000 | L5: =IFERROR(IF(LEN('Müşteri için Hesap'!I4)=0,"",'Müşteri için Hesap'!I4),"-") -> KREDİ KARTI | M5: =IFERROR(IF(LEN('Müşteri için Hesap'!J4)=0,"",'Müşteri için Hesap'!J4),"-") -> 69920.4 | U5: {=IFERROR(INDEX($B$4:$B$145, SMALL(IF((LEN($B$4:$B$145)<>0),ROW($B$4:$B$145)-ROW($B$3),"0"),ROW(B5)-ROW($B$3)) ),"0")} -> 45 DERECE | V5: {=IFERROR(INDEX($A$4:$A$145,MATCH(0,COUNTIF($V$3:V4,$A$4:$A$145),0)),"0")} -> BACA UZATMASI | W5: 1 | X5: =U5*W5 -> #VALUE! | Y5: =W5*V5 -> #VALUE!
A6: BACA DİRSEĞİ | B6: YOK | C6: 0 | D6: =IFERROR(IF(AND(LEN(A6)=0,LEN(B6)=0),"",IF(LEN(B6)=0,A6,A6&"-"&B6)),"") -> BACA DİRSEĞİ-YOK | F6: =IFERROR(IF(LEN('Müşteri için Hesap'!B5)=0,"",'Müşteri için Hesap'!B5),"-") -> DOĞALGAZ TESİSATI | G6: =IFERROR(IF(LEN('Müşteri için Hesap'!C5)=0,"",'Müşteri için Hesap'!C5),"-") -> ÇELİK_BORU | H6: =IFERROR(IF(LEN('Müşteri için Hesap'!D5)=0,"",'Müşteri için Hesap'!D5),"-") -> 1 | I6: =IFERROR(IF(LEN('Müşteri için Hesap'!E5)=0,"",'Müşteri için Hesap'!E5),"-") -> 4000 | J6: =IFERROR(IF(LEN('Müşteri için Hesap'!F5)=0,"",'Müşteri için Hesap'!F5),"-") -> 4000 | L6: =IFERROR(IF(LEN('Müşteri için Hesap'!I5)=0,"",'Müşteri için Hesap'!I5),"-") -> 12 AY SENET | M6: =IFERROR(IF(LEN('Müşteri için Hesap'!J5)=0,"",'Müşteri için Hesap'!J5),"-") -> 71191.68 | U6: {=IFERROR(INDEX($B$4:$B$145, SMALL(IF((LEN($B$4:$B$145)<>0),ROW($B$4:$B$145)-ROW($B$3),"0"),ROW(#REF!)-ROW($B$3)) ),"0")} -> 0 | V6: {=IFERROR(INDEX($A$4:$A$145,MATCH(0,COUNTIF($V$3:V5,$A$4:$A$145),0)),"0")} -> CAM MENFEZ | W6: 1 | X6: =U6*W6 -> 0 | Y6: =W6*V6 -> #VALUE!
A7: BACA UZATMASI | B7: 1 METRE | C7: 1000 | D7: =IFERROR(IF(AND(LEN(A7)=0,LEN(B7)=0),"",IF(LEN(B7)=0,A7,A7&"-"&B7)),"") -> BACA UZATMASI-1 METRE | F7: =IFERROR(IF(LEN('Müşteri için Hesap'!B6)=0,"",'Müşteri için Hesap'!B6),"-") -> RADYATÖR | G7: =IFERROR(IF(LEN('Müşteri için Hesap'!C6)=0,"",'Müşteri için Hesap'!C6),"-") -> WARMHAUS | H7: =IFERROR(IF(LEN('Müşteri için Hesap'!D6)=0,"",'Müşteri için Hesap'!D6),"-") -> 5 | I7: =IFERROR(IF(LEN('Müşteri için Hesap'!E6)=0,"",'Müşteri için Hesap'!E6),"-") -> 1850 | J7: =IFERROR(IF(LEN('Müşteri için Hesap'!F6)=0,"",'Müşteri için Hesap'!F6),"-") -> 9250 | L7: =IFERROR(IF(LEN('Müşteri için Hesap'!I6)=0,"",'Müşteri için Hesap'!I6),"-") -> 15 AY SENET | M7: =IFERROR(IF(LEN('Müşteri için Hesap'!J6)=0,"",'Müşteri için Hesap'!J6),"-") -> 73098.6 | U7: {=IFERROR(INDEX($B$4:$B$145, SMALL(IF((LEN($B$4:$B$145)<>0),ROW($B$4:$B$145)-ROW($B$3),"0"),ROW(#REF!)-ROW($B$3)) ),"0")} -> 0 | V7: {=IFERROR(INDEX($A$4:$A$145,MATCH(0,COUNTIF($V$3:V6,$A$4:$A$145),0)),"0")} -> DOĞALGAZ TESİSATI | W7: 1 | X7: =U7*W7 -> 0 | Y7: =W7*V7 -> #VALUE!
A8: BACA UZATMASI | B8: 50 CM | C8: 750 | D8: =IFERROR(IF(AND(LEN(A8)=0,LEN(B8)=0),"",IF(LEN(B8)=0,A8,A8&"-"&B8)),"") -> BACA UZATMASI-50 CM | F8: =IFERROR(IF(LEN('Müşteri için Hesap'!B7)=0,"",'Müşteri için Hesap'!B7),"-") -> RADYATÖR VANASI | G8: =IFERROR(IF(LEN('Müşteri için Hesap'!C7)=0,"",'Müşteri için Hesap'!C7),"-") -> KALDE | H8: =IFERROR(IF(LEN('Müşteri için Hesap'!D7)=0,"",'Müşteri için Hesap'!D7),"-") -> 14 | I8: =IFERROR(IF(LEN('Müşteri için Hesap'!E7)=0,"",'Müşteri için Hesap'!E7),"-") -> 105 | J8: =IFERROR(IF(LEN('Müşteri için Hesap'!F7)=0,"",'Müşteri için Hesap'!F7),"-") -> 1470 | L8: =IFERROR(IF(LEN('Müşteri için Hesap'!I7)=0,"",'Müşteri için Hesap'!I7),"-") -> 18 AY SENET | M8: =IFERROR(IF(LEN('Müşteri için Hesap'!J7)=0,"",'Müşteri için Hesap'!J7),"-") -> 75005.52 | U8: {=IFERROR(INDEX($B$4:$B$145, SMALL(IF((LEN($B$4:$B$145)<>0),ROW($B$4:$B$145)-ROW($B$3),"0"),ROW(#REF!)-ROW($B$3)) ),"0")} -> 0 | V8: {=IFERROR(INDEX($A$4:$A$145,MATCH(0,COUNTIF($V$3:V7,$A$4:$A$145),0)),"0")} -> ELEKTİRİK TESİSATI | W8: 1 | X8: =U8*W8 -> 0 | Y8: =W8*V8 -> #VALUE!
A9: CAM MENFEZ | B9: VAR | C9: 250 | D9: =IFERROR(IF(AND(LEN(A9)=0,LEN(B9)=0),"",IF(LEN(B9)=0,A9,A9&"-"&B9)),"") -> CAM MENFEZ-VAR | F9: =IFERROR(IF(LEN('Müşteri için Hesap'!B8)=0,"",'Müşteri için Hesap'!B8),"-") -> ODA TERMOSTATI | G9: =IFERROR(IF(LEN('Müşteri için Hesap'!C8)=0,"",'Müşteri için Hesap'!C8),"-") -> AİRFELL_KABLOSUZ_TERMOSTAT | H9: =IFERROR(IF(LEN('Müşteri için Hesap'!D8)=0,"",'Müşteri için Hesap'!D8),"-") -> 1 | I9: =IFERROR(IF(LEN('Müşteri için Hesap'!E8)=0,"",'Müşteri için Hesap'!E8),"-") -> 1000 | J9: =IFERROR(IF(LEN('Müşteri için Hesap'!F8)=0,"",'Müşteri için Hesap'!F8),"-") -> 1000 | U9: {=IFERROR(INDEX($B$4:$B$145, SMALL(IF((LEN($B$4:$B$145)<>0),ROW($B$4:$B$145)-ROW($B$3),"0"),ROW(#REF!)-ROW($B$3)) ),"0")} -> 0 | V9: {=IFERROR(INDEX($A$4:$A$145,MATCH(0,COUNTIF($V$3:V8,$A$4:$A$145),0)),"0")} -> EXTRA ISCILIK | W9: 1 | X9: =U9*W9 -> 0 | Y9: =W9*V9 -> #VALUE!
A10: CAM MENFEZ | B10: YOK | C10: 0 | D10: =IFERROR(IF(AND(LEN(A10)=0,LEN(B10)=0),"",IF(LEN(B10)=0,A10,A10&"-"&B10)),"") -> CAM MENFEZ-YOK | F10: =IFERROR(IF(LEN('Müşteri için Hesap'!B9)=0,"",'Müşteri için Hesap'!B9),"-") -> KOMBİ DOLABI | G10: =IFERROR(IF(LEN('Müşteri için Hesap'!C9)=0,"",'Müşteri için Hesap'!C9),"-") -> VAR | H10: =IFERROR(IF(LEN('Müşteri için Hesap'!D9)=0,"",'Müşteri için Hesap'!D9),"-") -> 1 | I10: =IFERROR(IF(LEN('Müşteri için Hesap'!E9)=0,"",'Müşteri için Hesap'!E9),"-") -> 1000 | J10: =IFERROR(IF(LEN('Müşteri için Hesap'!F9)=0,"",'Müşteri için Hesap'!F9),"-") -> 1000 | U10: {=IFERROR(INDEX($B$4:$B$145, SMALL(IF((LEN($B$4:$B$145)<>0),ROW($B$4:$B$145)-ROW($B$3),"0"),ROW(#REF!)-ROW($B$3)) ),"0")} -> 0 | V10: {=IFERROR(INDEX($A$4:$A$145,MATCH(0,COUNTIF($V$3:V9,$A$4:$A$145),0)),"0")} -> HAVLUPAN | W10: 1 | X10: =U10*W10 -> 0 | Y10: =W10*V10 -> #VALUE!
A11: DOĞALGAZ TESİSATI | B11: ÇELİK_BORU | C11: 4000 | D11: =IFERROR(IF(AND(LEN(A11)=0,LEN(B11)=0),"",IF(LEN(B11)=0,A11,A11&"-"&B11)),"") -> DOĞALGAZ TESİSATI-ÇELİK_BORU | F11: =IFERROR(IF(LEN('Müşteri için Hesap'!B10)=0,"",'Müşteri için Hesap'!B10),"-") -> HAVLUPAN | G11: VAR | H11: =IFERROR(IF(LEN('Müşteri için Hesap'!D10)=0,"",'Müşteri için Hesap'!D10),"-") -> 1 | I11: =IFERROR(IF(LEN('Müşteri için Hesap'!E10)=0,"",'Müşteri için Hesap'!E10),"-") -> 750 | J11: =IFERROR(IF(LEN('Müşteri için Hesap'!F10)=0,"",'Müşteri için Hesap'!F10),"-") -> 750 | U11: {=IFERROR(INDEX($B$4:$B$145, SMALL(IF((LEN($B$4:$B$145)<>0),ROW($B$4:$B$145)-ROW($B$3),"0"),ROW(#REF!)-ROW($B$3)) ),"0")} -> 0 | V11: {=IFERROR(INDEX($A$4:$A$145,MATCH(0,COUNTIF($V$3:V10,$A$4:$A$145),0)),"0")} -> İŞÇİLİK | W11: 1 | X11: =U11*W11 -> 0 | Y11: =W11*V11 -> #VALUE!
A12: DOĞALGAZ TESİSATI | B12: ESNEK_BORU | C12: 8000 | D12: =IFERROR(IF(AND(LEN(A12)=0,LEN(B12)=0),"",IF(LEN(B12)=0,A12,A12&"-"&B12)),"") -> DOĞALGAZ TESİSATI-ESNEK_BORU | F12: =IFERROR(IF(LEN('Müşteri için Hesap'!B11)=0,"",'Müşteri için Hesap'!B11),"-") -> BACA UZATMASI | G12: =IFERROR(IF(LEN('Müşteri için Hesap'!C11)=0,"",'Müşteri için Hesap'!C11),"-") -> YOK | H12: =IFERROR(IF(LEN('Müşteri için Hesap'!D11)=0,"",'Müşteri için Hesap'!D11),"-") -> 1 | I12: =IFERROR(IF(LEN('Müşteri için Hesap'!E11)=0,"",'Müşteri için Hesap'!E11),"-") -> - | J12: =IFERROR(IF(LEN('Müşteri için Hesap'!F11)=0,"",'Müşteri için Hesap'!F11),"-") -> - | U12: {=IFERROR(INDEX($B$4:$B$145, SMALL(IF((LEN($B$4:$B$145)<>0),ROW($B$4:$B$145)-ROW($B$3),"0"),ROW(#REF!)-ROW($B$3)) ),"0")} -> 0 | V12: {=IFERROR(INDEX($A$4:$A$145,MATCH(0,COUNTIF($V$3:V11,$A$4:$A$145),0)),"0")} -> KALORİFER TESİSATI | W12: 1 | X12: =U12*W12 -> 0 | Y12: =W12*V12 -> #VALUE!
A13: ELEKTİRİK TESİSATI | B13: VAR | C13: 250 | D13: =IFERROR(IF(AND(LEN(A13)=0,LEN(B13)=0),"",IF(LEN(B13)=0,A13,A13&"-"&B13)),"") -> ELEKTİRİK TESİSATI-VAR | F13: =IFERROR(IF(LEN('Müşteri için Hesap'!B12)=0,"",'Müşteri için Hesap'!B12),"-") -> BACA DİRSEĞİ | G13: =IFERROR(IF(LEN('Müşteri için Hesap'!C12)=0,"",'Müşteri için Hesap'!C12),"-") -> YOK | H13: =IFERROR(IF(LEN('Müşteri için Hesap'!D12)=0,"",'Müşteri için Hesap'!D12),"-") -> 1 | I13: =IFERROR(IF(LEN('Müşteri için Hesap'!E12)=0,"",'Müşteri için Hesap'!E12),"-") -> 0 | J13: =IFERROR(IF(LEN('Müşteri için Hesap'!F12)=0,"",'Müşteri için Hesap'!F12),"-") -> 0 | U13: {=IFERROR(INDEX($B$4:$B$145, SMALL(IF((LEN($B$4:$B$145)<>0),ROW($B$4:$B$145)-ROW($B$3),"0"),ROW(B6)-ROW($B$3)) ),"0")} -> YOK | V13: {=IFERROR(INDEX($A$4:$A$145,MATCH(0,COUNTIF($V$3:V12,$A$4:$A$145),0)),"0")} -> KOMBİ | W13: 1 | X13: =U13*W13 -> #VALUE! | Y13: =W13*V13 -> #VALUE!
A14: ELEKTİRİK TESİSATI | B14: YOK | C14: 0 | D14: =IFERROR(IF(AND(LEN(A14)=0,LEN(B14)=0),"",IF(LEN(B14)=0,A14,A14&"-"&B14)),"") -> ELEKTİRİK TESİSATI-YOK | F14: =IFERROR(IF(LEN('Müşteri için Hesap'!B13)=0,"",'Müşteri için Hesap'!B13),"-") -> CAM MENFEZ | G14: =IFERROR(IF(LEN('Müşteri için Hesap'!C13)=0,"",'Müşteri için Hesap'!C13),"-") -> VAR | H14: =IFERROR(IF(LEN('Müşteri için Hesap'!D13)=0,"",'Müşteri için Hesap'!D13),"-") -> 1 | I14: =IFERROR(IF(LEN('Müşteri için Hesap'!E13)=0,"",'Müşteri için Hesap'!E13),"-") -> 250 | J14: =IFERROR(IF(LEN('Müşteri için Hesap'!F13)=0,"",'Müşteri için Hesap'!F13),"-") -> 250 | U14: {=IFERROR(INDEX($B$4:$B$145, SMALL(IF((LEN($B$4:$B$145)<>0),ROW($B$4:$B$145)-ROW($B$3),"0"),ROW(B7)-ROW($B$3)) ),"0")} -> 1 METRE | V14: {=IFERROR(INDEX($A$4:$A$145,MATCH(0,COUNTIF($V$3:V13,$A$4:$A$145),0)),"0")} -> KOMBİ DOLABI | W14: 1 | X14: =U14*W14 -> #VALUE! | Y14: =W14*V14 -> #VALUE!
A15: EXTRA ISCILIK | B15: VAR | C15: 1000 | D15: =IFERROR(IF(AND(LEN(A15)=0,LEN(B15)=0),"",IF(LEN(B15)=0,A15,A15&"-"&B15)),"") -> EXTRA ISCILIK-VAR | F15: =IFERROR(IF(LEN('Müşteri için Hesap'!B14)=0,"",'Müşteri için Hesap'!B14),"-") -> ELEKTİRİK TESİSATI | G15: =IFERROR(IF(LEN('Müşteri için Hesap'!C14)=0,"",'Müşteri için Hesap'!C14),"-") -> VAR | H15: =IFERROR(IF(LEN('Müşteri için Hesap'!D14)=0,"",'Müşteri için Hesap'!D14),"-") -> 1 | I15: =IFERROR(IF(LEN('Müşteri için Hesap'!E14)=0,"",'Müşteri için Hesap'!E14),"-") -> 250 | J15: =IFERROR(IF(LEN('Müşteri için Hesap'!F14)=0,"",'Müşteri için Hesap'!F14),"-") -> 250 | U15: {=IFERROR(INDEX($B$4:$B$145, SMALL(IF((LEN($B$4:$B$145)<>0),ROW($B$4:$B$145)-ROW($B$3),"0"),ROW(B8)-ROW($B$3)) ),"0")} -> 50 CM | V15: {=IFERROR(INDEX($A$4:$A$145,MATCH(0,COUNTIF($V$3:V14,$A$4:$A$145),0)),"0")} -> ODA TERMOSTATI | W15: 1 | X15: =U15*W15 -> #VALUE! | Y15: =W15*V15 -> #VALUE!
A16: EXTRA ISCILIK | B16: YOK | C16: 0 | D16: =IFERROR(IF(AND(LEN(A16)=0,LEN(B16)=0),"",IF(LEN(B16)=0,A16,A16&"-"&B16)),"") -> EXTRA ISCILIK-YOK | F16: =IFERROR(IF(LEN('Müşteri için Hesap'!B15)=0,"",'Müşteri için Hesap'!B15),"-") -> İŞÇİLİK | G16: =IFERROR(IF(LEN('Müşteri için Hesap'!C15)=0,"",'Müşteri için Hesap'!C15),"-") -> KOMPLE | H16: =IFERROR(IF(LEN('Müşteri için Hesap'!D15)=0,"",'Müşteri için Hesap'!D15),"-") -> 1 | I16: =IFERROR(IF(LEN('Müşteri için Hesap'!E15)=0,"",'Müşteri için Hesap'!E15),"-") -> 7000 | J16: =IFERROR(IF(LEN('Müşteri için Hesap'!F15)=0,"",'Müşteri için Hesap'!F15),"-") -> 7000 | U16: {=IFERROR(INDEX($B$4:$B$145, SMALL(IF((LEN($B$4:$B$145)<>0),ROW($B$4:$B$145)-ROW($B$3),"0"),ROW(#REF!)-ROW($B$3)) ),"0")} -> 0 | V16: {=IFERROR(INDEX($A$4:$A$145,MATCH(0,COUNTIF($V$3:V15,$A$4:$A$145),0)),"0")} -> RADYATÖR | W16: 1 | X16: =U16*W16 -> 0 | Y16: =W16*V16 -> #VALUE!
A17: HAVLUPAN | B17: KROM | C17: 750 | D17: =IFERROR(IF(AND(LEN(A17)=0,LEN(B17)=0),"",IF(LEN(B17)=0,A17,A17&"-"&B17)),"") -> HAVLUPAN-KROM | F17: =IFERROR(IF(LEN('Müşteri için Hesap'!B16)=0,"",'Müşteri için Hesap'!B16),"-") -> FİRMA GİDERİ | G17: =IFERROR(IF(LEN('Müşteri için Hesap'!C16)=0,"",'Müşteri için Hesap'!C16),"-") -> VAR | H17: =IFERROR(IF(LEN('Müşteri için Hesap'!D16)=0,"",'Müşteri için Hesap'!D16),"-") -> 1 | I17: =IFERROR(IF(LEN('Müşteri için Hesap'!E16)=0,"",'Müşteri için Hesap'!E16),"-") -> 1000 | J17: =IFERROR(IF(LEN('Müşteri için Hesap'!F16)=0,"",'Müşteri için Hesap'!F16),"-") -> 1000 | U17: {=IFERROR(INDEX($B$4:$B$145, SMALL(IF((LEN($B$4:$B$145)<>0),ROW($B$4:$B$145)-ROW($B$3),"0"),ROW(#REF!)-ROW($B$3)) ),"0")} -> 0 | V17: {=IFERROR(INDEX($A$4:$A$145,MATCH(0,COUNTIF($V$3:V16,$A$4:$A$145),0)),"0")} -> RADYATÖR VANASI | W17: 1 | X17: =U17*W17 -> 0 | Y17: =W17*V17 -> #VALUE!
A18: HAVLUPAN | B18: BEYAZ | C18: 750 | D18: =IFERROR(IF(AND(LEN(A18)=0,LEN(B18)=0),"",IF(LEN(B18)=0,A18,A18&"-"&B18)),"") -> HAVLUPAN-BEYAZ | F18: =IFERROR(IF(LEN('Müşteri için Hesap'!B17)=0,"",'Müşteri için Hesap'!B17),"-") -> BACA UZATMASI | G18: =IFERROR(IF(LEN('Müşteri için Hesap'!C17)=0,"",'Müşteri için Hesap'!C17),"-") -> YOK | H18: =IFERROR(IF(LEN('Müşteri için Hesap'!D17)=0,"",'Müşteri için Hesap'!D17),"-") -> 1 | I18: =IFERROR(IF(LEN('Müşteri için Hesap'!E17)=0,"",'Müşteri için Hesap'!E17),"-") -> - | J18: =IFERROR(IF(LEN('Müşteri için Hesap'!F17)=0,"",'Müşteri için Hesap'!F17),"-") -> - | U18: {=IFERROR(INDEX($B$4:$B$145, SMALL(IF((LEN($B$4:$B$145)<>0),ROW($B$4:$B$145)-ROW($B$3),"0"),ROW(#REF!)-ROW($B$3)) ),"0")} -> 0 | V18: {=IFERROR(INDEX($A$4:$A$145,MATCH(0,COUNTIF($V$3:V17,$A$4:$A$145),0)),"0")} -> FİRMA GİDERİ | W18: 1 | X18: =U18*W18 -> 0 | Y18: =W18*V18 -> #VALUE!
A19: İŞÇİLİK | B19: MONTAJ | C19: 5000 | D19: =IFERROR(IF(AND(LEN(A19)=0,LEN(B19)=0),"",IF(LEN(B19)=0,A19,A19&"-"&B19)),"") -> İŞÇİLİK-MONTAJ | F19: =IFERROR(IF(LEN('Müşteri için Hesap'!#REF!)=0,"",'Müşteri için Hesap'!#REF!),"-") -> - | G19: =IFERROR(IF(LEN('Müşteri için Hesap'!#REF!)=0,"",'Müşteri için Hesap'!#REF!),"-") -> - | H19: =IFERROR(IF(LEN('Müşteri için Hesap'!#REF!)=0,"",'Müşteri için Hesap'!#REF!),"-") -> - | I19: =IFERROR(IF(LEN('Müşteri için Hesap'!#REF!)=0,"",'Müşteri için Hesap'!#REF!),"-") -> - | J19: =IFERROR(IF(LEN('Müşteri için Hesap'!#REF!)=0,"",'Müşteri için Hesap'!#REF!),"-") -> - | U19: {=IFERROR(INDEX($B$4:$B$145, SMALL(IF((LEN($B$4:$B$145)<>0),ROW($B$4:$B$145)-ROW($B$3),"0"),ROW(#REF!)-ROW($B$3)) ),"0")} -> 0 | V19: {=IFERROR(INDEX($A$4:$A$145,MATCH(0,COUNTIF($V$3:V18,$A$4:$A$145),0)),"0")} -> 0 | W19: 1 | X19: =U19*W19 -> 0 | Y19: =W19*V19 -> 0
A20: İŞÇİLİK | B20: KOMPLE | C20: 7000 | D20: =IFERROR(IF(AND(LEN(A20)=0,LEN(B20)=0),"",IF(LEN(B20)=0,A20,A20&"-"&B20)),"") -> İŞÇİLİK-KOMPLE | F20: =IFERROR(IF(LEN('Müşteri için Hesap'!#REF!)=0,"",'Müşteri için Hesap'!#REF!),"-") -> - | G20: =IFERROR(IF(LEN('Müşteri için Hesap'!#REF!)=0,"",'Müşteri için Hesap'!#REF!),"-") -> - | H20: =IFERROR(IF(LEN('Müşteri için Hesap'!#REF!)=0,"",'Müşteri için Hesap'!#REF!),"-") -> - | I20: =IFERROR(IF(LEN('Müşteri için Hesap'!#REF!)=0,"",'Müşteri için Hesap'!#REF!),"-") -> - | J20: =IFERROR(IF(LEN('Müşteri için Hesap'!#REF!)=0,"",'Müşteri için Hesap'!#REF!),"-") -> - | U20: {=IFERROR(INDEX($B$4:$B$145, SMALL(IF((LEN($B$4:$B$145)<>0),ROW($B$4:$B$145)-ROW($B$3),"0"),ROW(#REF!)-ROW($B$3)) ),"0")} -> 0 | V20: {=IFERROR(INDEX($A$4:$A$145,MATCH(0,COUNTIF($V$3:V19,$A$4:$A$145),0)),"0")} -> 0 | W20: 1 | X20: =U20*W20 -> 0 | Y20: =W20*V20 -> 0
A21: İŞÇİLİK | B21: KOMBİ + GAZ | C21: 4000 | D21: =IFERROR(IF(AND(LEN(A21)=0,LEN(B21)=0),"",IF(LEN(B21)=0,A21,A21&"-"&B21)),"") -> İŞÇİLİK-KOMBİ + GAZ | F21: =IFERROR(IF(LEN('Müşteri için Hesap'!B18)=0,"",'Müşteri için Hesap'!B18),"-") | G21: =IFERROR(IF(LEN('Müşteri için Hesap'!C18)=0,"",'Müşteri için Hesap'!C18),"-") | H21: =IFERROR(IF(LEN('Müşteri için Hesap'!D18)=0,"",'Müşteri için Hesap'!D18),"-") | I21: =IFERROR(IF(LEN('Müşteri için Hesap'!E18)=0,"",'Müşteri için Hesap'!E18),"-") | J21: =IFERROR(IF(LEN('Müşteri için Hesap'!F18)=0,"",'Müşteri için Hesap'!F18),"-") | U21: {=IFERROR(INDEX($B$4:$B$145, SMALL(IF((LEN($B$4:$B$145)<>0),ROW($B$4:$B$145)-ROW($B$3),"0"),ROW(#REF!)-ROW($B$3)) ),"0")} -> 0 | V21: {=IFERROR(INDEX($A$4:$A$145,MATCH(0,COUNTIF($V$3:V20,$A$4:$A$145),0)),"0")} -> 0 | W21: 1 | X21: =U21*W21 -> 0 | Y21: =W21*V21 -> 0
A22: KALORİFER TESİSATI | B22: KOMPLE | C22: 5000 | D22: =IFERROR(IF(AND(LEN(A22)=0,LEN(B22)=0),"",IF(LEN(B22)=0,A22,A22&"-"&B22)),"") -> KALORİFER TESİSATI-KOMPLE | F22: =IFERROR(IF(LEN('Müşteri için Hesap'!B19)=0,"",'Müşteri için Hesap'!B19),"-") | G22: =IFERROR(IF(LEN('Müşteri için Hesap'!C19)=0,"",'Müşteri için Hesap'!C19),"-") | H22: =IFERROR(IF(LEN('Müşteri için Hesap'!D19)=0,"",'Müşteri için Hesap'!D19),"-") | I22: =IFERROR(IF(LEN('Müşteri için Hesap'!E19)=0,"",'Müşteri için Hesap'!E19),"-") | J22: =IFERROR(IF(LEN('Müşteri için Hesap'!F19)=0,"",'Müşteri için Hesap'!F19),"-") | U22: {=IFERROR(INDEX($B$4:$B$145, SMALL(IF((LEN($B$4:$B$145)<>0),ROW($B$4:$B$145)-ROW($B$3),"0"),ROW(#REF!)-ROW($B$3)) ),"0")} -> 0 | V22: {=IFERROR(INDEX($A$4:$A$145,MATCH(0,COUNTIF($V$3:V21,$A$4:$A$145),0)),"0")} -> 0 | W22: 1 | X22: =U22*W22 -> 0 | Y22: =W22*V22 -> 0
A23: KALORİFER TESİSATI | B23: ÖTELEME | C23: 2500 | D23: =IFERROR(IF(AND(LEN(A23)=0,LEN(B23)=0),"",IF(LEN(B23)=0,A23,A23&"-"&B23)),"") -> KALORİFER TESİSATI-ÖTELEME | F23: =IFERROR(IF(LEN('Müşteri için Hesap'!B20)=0,"",'Müşteri için Hesap'!B20),"-") | G23: =IFERROR(IF(LEN('Müşteri için Hesap'!C20)=0,"",'Müşteri için Hesap'!C20),"-") | H23: =IFERROR(IF(LEN('Müşteri için Hesap'!D20)=0,"",'Müşteri için Hesap'!D20),"-") | I23: =IFERROR(IF(LEN('Müşteri için Hesap'!E20)=0,"",'Müşteri için Hesap'!E20),"-") | J23: =IFERROR(IF(LEN('Müşteri için Hesap'!F20)=0,"",'Müşteri için Hesap'!F20),"-") | U23: {=IFERROR(INDEX($B$4:$B$145, SMALL(IF((LEN($B$4:$B$145)<>0),ROW($B$4:$B$145)-ROW($B$3),"0"),ROW(#REF!)-ROW($B$3)) ),"0")} -> 0 | V23: {=IFERROR(INDEX($A$4:$A$145,MATCH(0,COUNTIF($V$3:V22,$A$4:$A$145),0)),"0")} -> 0 | W23: 1 | X23: =U23*W23 -> 0 | Y23: =W23*V23 -> 0
A24: KALORİFER TESİSATI | B24: HAZIR | D24: =IFERROR(IF(AND(LEN(A24)=0,LEN(B24)=0),"",IF(LEN(B24)=0,A24,A24&"-"&B24)),"") -> KALORİFER TESİSATI-HAZIR | F24: =IFERROR(IF(LEN('Müşteri için Hesap'!B21)=0,"",'Müşteri için Hesap'!B21),"-") | G24: =IFERROR(IF(LEN('Müşteri için Hesap'!C21)=0,"",'Müşteri için Hesap'!C21),"-") | H24: =IFERROR(IF(LEN('Müşteri için Hesap'!D21)=0,"",'Müşteri için Hesap'!D21),"-") | I24: =IFERROR(IF(LEN('Müşteri için Hesap'!E21)=0,"",'Müşteri için Hesap'!E21),"-") | J24: =IFERROR(IF(LEN('Müşteri için Hesap'!F21)=0,"",'Müşteri için Hesap'!F21),"-") | U24: {=IFERROR(INDEX($B$4:$B$145, SMALL(IF((LEN($B$4:$B$145)<>0),ROW($B$4:$B$145)-ROW($B$3),"0"),ROW(#REF!)-ROW($B$3)) ),"0")} -> 0 | V24: {=IFERROR(INDEX($A$4:$A$145,MATCH(0,COUNTIF($V$3:V23,$A$4:$A$145),0)),"0")} -> 0 | W24: 1 | X24: =U24*W24 -> 0 | Y24: =W24*V24 -> 0
A25: KOMBİ | B25: BOSCH_CONDENCE1200İ_20kW | C25: 25500 | D25: =IFERROR(IF(AND(LEN(A25)=0,LEN(B25)=0),"",IF(LEN(B25)=0,A25,A25&"-"&B25)),"") -> KOMBİ-BOSCH_CONDENCE1200İ_20kW | F25: =IFERROR(IF(LEN('Müşteri için Hesap'!B22)=0,"",'Müşteri için Hesap'!B22),"-") | G25: =IFERROR(IF(LEN('Müşteri için Hesap'!C22)=0,"",'Müşteri için Hesap'!C22),"-") | H25: =IFERROR(IF(LEN('Müşteri için Hesap'!D22)=0,"",'Müşteri için Hesap'!D22),"-") | I25: =IFERROR(IF(LEN('Müşteri için Hesap'!E22)=0,"",'Müşteri için Hesap'!E22),"-") | J25: =IFERROR(IF(LEN('Müşteri için Hesap'!F22)=0,"",'Müşteri için Hesap'!F22),"-") | U25: {=IFERROR(INDEX($B$4:$B$145, SMALL(IF((LEN($B$4:$B$145)<>0),ROW($B$4:$B$145)-ROW($B$3),"0"),ROW(B9)-ROW($B$3)) ),"0")} -> VAR | V25: {=IFERROR(INDEX($A$4:$A$145,MATCH(0,COUNTIF($V$3:V24,$A$4:$A$145),0)),"0")} -> 0 | W25: 1 | X25: =U25*W25 -> #VALUE! | Y25: =W25*V25 -> 0
A26: KOMBİ | B26: BOSCH_CONDENCE2200İ_20kW | C26: 27000 | D26: =IFERROR(IF(AND(LEN(A26)=0,LEN(B26)=0),"",IF(LEN(B26)=0,A26,A26&"-"&B26)),"") -> KOMBİ-BOSCH_CONDENCE2200İ_20kW | F26: =IFERROR(IF(LEN('Müşteri için Hesap'!B23)=0,"",'Müşteri için Hesap'!B23),"-") | G26: =IFERROR(IF(LEN('Müşteri için Hesap'!C23)=0,"",'Müşteri için Hesap'!C23),"-") | H26: =IFERROR(IF(LEN('Müşteri için Hesap'!D23)=0,"",'Müşteri için Hesap'!D23),"-") | I26: =IFERROR(IF(LEN('Müşteri için Hesap'!E23)=0,"",'Müşteri için Hesap'!E23),"-") | J26: =IFERROR(IF(LEN('Müşteri için Hesap'!F23)=0,"",'Müşteri için Hesap'!F23),"-") | U26: {=IFERROR(INDEX($B$4:$B$145, SMALL(IF((LEN($B$4:$B$145)<>0),ROW($B$4:$B$145)-ROW($B$3),"0"),ROW(B10)-ROW($B$3)) ),"0")} -> YOK | V26: {=IFERROR(INDEX($A$4:$A$145,MATCH(0,COUNTIF($V$3:V25,$A$4:$A$145),0)),"0")} -> 0 | W26: 1 | X26: =U26*W26 -> #VALUE! | Y26: =W26*V26 -> 0
A27: KOMBİ | B27: BOSCH_CONDENCE1200İ_24kW | C27: 27000 | D27: =IFERROR(IF(AND(LEN(A27)=0,LEN(B27)=0),"",IF(LEN(B27)=0,A27,A27&"-"&B27)),"") -> KOMBİ-BOSCH_CONDENCE1200İ_24kW | F27: =IFERROR(IF(LEN('Müşteri için Hesap'!B24)=0,"",'Müşteri için Hesap'!B24),"-") | G27: =IFERROR(IF(LEN('Müşteri için Hesap'!C24)=0,"",'Müşteri için Hesap'!C24),"-") | H27: =IFERROR(IF(LEN('Müşteri için Hesap'!D24)=0,"",'Müşteri için Hesap'!D24),"-") | I27: =IFERROR(IF(LEN('Müşteri için Hesap'!E24)=0,"",'Müşteri için Hesap'!E24),"-") | J27: =IFERROR(IF(LEN('Müşteri için Hesap'!F24)=0,"",'Müşteri için Hesap'!F24),"-") | U27: {=IFERROR(INDEX($B$4:$B$145, SMALL(IF((LEN($B$4:$B$145)<>0),ROW($B$4:$B$145)-ROW($B$3),"0"),ROW(B11)-ROW($B$3)) ),"0")} -> ÇELİK_BORU | V27: {=IFERROR(INDEX($A$4:$A$145,MATCH(0,COUNTIF($V$3:V26,$A$4:$A$145),0)),"0")} -> 0 | W27: 1 | X27: =U27*W27 -> #VALUE! | Y27: =W27*V27 -> 0
A28: KOMBİ | B28: ECA_CİTİUS_24kW | C28: 25000 | D28: =IFERROR(IF(AND(LEN(A28)=0,LEN(B28)=0),"",IF(LEN(B28)=0,A28,A28&"-"&B28)),"") -> KOMBİ-ECA_CİTİUS_24kW
A29: KOMBİ | B29: ECA_PROTEUS_PREMİX_24kW | C29: 30000 | D29: =IFERROR(IF(AND(LEN(A29)=0,LEN(B29)=0),"",IF(LEN(B29)=0,A29,A29&"-"&B29)),"") -> KOMBİ-ECA_PROTEUS_PREMİX_24kW | U29: {=IFERROR(INDEX($B$4:$B$145, SMALL(IF((LEN($B$4:$B$145)<>0),ROW($B$4:$B$145)-ROW($B$3),"0"),ROW(B13)-ROW($B$3)) ),"0")} -> VAR | V29: {=IFERROR(INDEX($A$4:$A$145,MATCH(0,COUNTIF($V$3:V28,$A$4:$A$145),0)),"0")} -> 0 | W29: 1 | X29: =U29*W29 -> #VALUE! | Y29: =W29*V29 -> 0
A30: KOMBİ | B30: AİRFELL_MAESTRO_OPTİMUM_20kW | C30: 22000 | D30: =IFERROR(IF(AND(LEN(A30)=0,LEN(B30)=0),"",IF(LEN(B30)=0,A30,A30&"-"&B30)),"") -> KOMBİ-AİRFELL_MAESTRO_OPTİMUM_20kW | F30: =IFERROR(IF(LEN('Müşteri için Hesap'!B27)=0,"",'Müşteri için Hesap'!B27),"-") | G30: =IFERROR(IF(LEN('Müşteri için Hesap'!C27)=0,"",'Müşteri için Hesap'!C27),"-") | H30: =IFERROR(IF(LEN('Müşteri için Hesap'!D27)=0,"",'Müşteri için Hesap'!D27),"-") | I30: =IFERROR(IF(LEN('Müşteri için Hesap'!E27)=0,"",'Müşteri için Hesap'!E27),"-") -> Toplam Tutar | J30: =IFERROR(IF(LEN('Müşteri için Hesap'!F27)=0,"",'Müşteri için Hesap'!F27),"-") -> 52970 | U30: {=IFERROR(INDEX($B$4:$B$145, SMALL(IF((LEN($B$4:$B$145)<>0),ROW($B$4:$B$145)-ROW($B$3),"0"),ROW(B14)-ROW($B$3)) ),"0")} -> YOK | V30: {=IFERROR(INDEX($A$4:$A$145,MATCH(0,COUNTIF($V$3:V29,$A$4:$A$145),0)),"0")} -> 0 | W30: 1 | X30: =U30*W30 -> #VALUE! | Y30: =W30*V30 -> 0
A31: KOMBİ | B31: AİRFELL_MAESTRO_OPTİMUM_23kW | C31: 24000 | D31: =IFERROR(IF(AND(LEN(A31)=0,LEN(B31)=0),"",IF(LEN(B31)=0,A31,A31&"-"&B31)),"") -> KOMBİ-AİRFELL_MAESTRO_OPTİMUM_23kW | U31: {=IFERROR(INDEX($B$4:$B$145, SMALL(IF((LEN($B$4:$B$145)<>0),ROW($B$4:$B$145)-ROW($B$3),"0"),ROW(B16)-ROW($B$3)) ),"0")} -> YOK | V31: {=IFERROR(INDEX($A$4:$A$145,MATCH(0,COUNTIF($V$3:V30,$A$4:$A$145),0)),"0")} -> 0 | W31: 1 | X31: =U31*W31 -> #VALUE! | Y31: =W31*V31 -> 0
A32: KOMBİ DOLABI | B32: YOK | C32: 0 | D32: =IFERROR(IF(AND(LEN(A32)=0,LEN(B32)=0),"",IF(LEN(B32)=0,A32,A32&"-"&B32)),"") -> KOMBİ DOLABI-YOK | U32: {=IFERROR(INDEX($B$4:$B$145, SMALL(IF((LEN($B$4:$B$145)<>0),ROW($B$4:$B$145)-ROW($B$3),"0"),ROW(#REF!)-ROW($B$3)) ),"0")} -> 0 | V32: {=IFERROR(INDEX($A$4:$A$145,MATCH(0,COUNTIF($V$3:V31,$A$4:$A$145),0)),"0")} -> 0 | W32: 1 | X32: =U32*W32 -> 0 | Y32: =W32*V32 -> 0
A33: KOMBİ DOLABI | B33: VAR | C33: 1000 | D33: =IFERROR(IF(AND(LEN(A33)=0,LEN(B33)=0),"",IF(LEN(B33)=0,A33,A33&"-"&B33)),"") -> KOMBİ DOLABI-VAR | U33: {=IFERROR(INDEX($B$4:$B$145, SMALL(IF((LEN($B$4:$B$145)<>0),ROW($B$4:$B$145)-ROW($B$3),"0"),ROW(#REF!)-ROW($B$3)) ),"0")} -> 0 | V33: {=IFERROR(INDEX($A$4:$A$145,MATCH(0,COUNTIF($V$3:V32,$A$4:$A$145),0)),"0")} -> 0 | W33: 1 | X33: =U33*W33 -> 0 | Y33: =W33*V33 -> 0
A34: ODA TERMOSTATI | B34: AİRFELL_KABLOSUZ_TERMOSTAT | C34: 1000 | D34: =IFERROR(IF(AND(LEN(A34)=0,LEN(B34)=0),"",IF(LEN(B34)=0,A34,A34&"-"&B34)),"") -> ODA TERMOSTATI-AİRFELL_KABLOSUZ_TERMOSTAT | U34: {=IFERROR(INDEX($B$4:$B$145, SMALL(IF((LEN($B$4:$B$145)<>0),ROW($B$4:$B$145)-ROW($B$3),"0"),ROW(B17)-ROW($B$3)) ),"0")} -> KROM | V34: {=IFERROR(INDEX($A$4:$A$145,MATCH(0,COUNTIF($V$3:V33,$A$4:$A$145),0)),"0")} -> 0 | W34: 1 | X34: =U34*W34 -> #VALUE! | Y34: =W34*V34 -> 0
A35: ODA TERMOSTATI | B35: ECA_KABLOSUZ_TERMOSTAT | C35: 1500 | D35: =IFERROR(IF(AND(LEN(A35)=0,LEN(B35)=0),"",IF(LEN(B35)=0,A35,A35&"-"&B35)),"") -> ODA TERMOSTATI-ECA_KABLOSUZ_TERMOSTAT | U35: {=IFERROR(INDEX($B$4:$B$145, SMALL(IF((LEN($B$4:$B$145)<>0),ROW($B$4:$B$145)-ROW($B$3),"0"),ROW(B18)-ROW($B$3)) ),"0")} -> BEYAZ | V35: {=IFERROR(INDEX($A$4:$A$145,MATCH(0,COUNTIF($V$3:V34,$A$4:$A$145),0)),"0")} -> 0 | W35: 1 | X35: =U35*W35 -> #VALUE! | Y35: =W35*V35 -> 0
A36: ODA TERMOSTATI | B36: BOSCH_KABLOSUZ_TERMOSTAT | C36: 1500 | D36: =IFERROR(IF(AND(LEN(A36)=0,LEN(B36)=0),"",IF(LEN(B36)=0,A36,A36&"-"&B36)),"") -> ODA TERMOSTATI-BOSCH_KABLOSUZ_TERMOSTAT | U36: {=IFERROR(INDEX($B$4:$B$145, SMALL(IF((LEN($B$4:$B$145)<>0),ROW($B$4:$B$145)-ROW($B$3),"0"),ROW(B19)-ROW($B$3)) ),"0")} -> MONTAJ | V36: {=IFERROR(INDEX($A$4:$A$145,MATCH(0,COUNTIF($V$3:V35,$A$4:$A$145),0)),"0")} -> 0 | W36: 1 | X36: =U36*W36 -> #VALUE! | Y36: =W36*V36 -> 0
A37: ODA TERMOSTATI | B37: YOK | D37: =IFERROR(IF(AND(LEN(A37)=0,LEN(B37)=0),"",IF(LEN(B37)=0,A37,A37&"-"&B37)),"") -> ODA TERMOSTATI-YOK | U37: {=IFERROR(INDEX($B$4:$B$145, SMALL(IF((LEN($B$4:$B$145)<>0),ROW($B$4:$B$145)-ROW($B$3),"0"),ROW(B20)-ROW($B$3)) ),"0")} -> KOMPLE | V37: {=IFERROR(INDEX($A$4:$A$145,MATCH(0,COUNTIF($V$3:V36,$A$4:$A$145),0)),"0")} -> 0 | W37: 1 | X37: =U37*W37 -> #VALUE! | Y37: =W37*V37 -> 0
A38: RADYATÖR | B38: ECA | C38: 2250 | D38: =IFERROR(IF(AND(LEN(A38)=0,LEN(B38)=0),"",IF(LEN(B38)=0,A38,A38&"-"&B38)),"") -> RADYATÖR-ECA | U38: {=IFERROR(INDEX($B$4:$B$145, SMALL(IF((LEN($B$4:$B$145)<>0),ROW($B$4:$B$145)-ROW($B$3),"0"),ROW(B21)-ROW($B$3)) ),"0")} -> KOMBİ + GAZ | V38: {=IFERROR(INDEX($A$4:$A$145,MATCH(0,COUNTIF($V$3:V37,$A$4:$A$145),0)),"0")} -> 0 | W38: 1 | X38: =U38*W38 -> #VALUE! | Y38: =W38*V38 -> 0
A39: RADYATÖR | B39: WARMHAUS | C39: 1850 | D39: =IFERROR(IF(AND(LEN(A39)=0,LEN(B39)=0),"",IF(LEN(B39)=0,A39,A39&"-"&B39)),"") -> RADYATÖR-WARMHAUS | U39: {=IFERROR(INDEX($B$4:$B$145, SMALL(IF((LEN($B$4:$B$145)<>0),ROW($B$4:$B$145)-ROW($B$3),"0"),ROW(B22)-ROW($B$3)) ),"0")} -> KOMPLE | V39: {=IFERROR(INDEX($A$4:$A$145,MATCH(0,COUNTIF($V$3:V38,$A$4:$A$145),0)),"0")} -> 0 | W39: 1 | X39: =U39*W39 -> #VALUE! | Y39: =W39*V39 -> 0
A40: RADYATÖR VANASI | B40: KALDE | C40: 105 | D40: =IFERROR(IF(AND(LEN(A40)=0,LEN(B40)=0),"",IF(LEN(B40)=0,A40,A40&"-"&B40)),"") -> RADYATÖR VANASI-KALDE | U40: {=IFERROR(INDEX($B$4:$B$145, SMALL(IF((LEN($B$4:$B$145)<>0),ROW($B$4:$B$145)-ROW($B$3),"0"),ROW(B23)-ROW($B$3)) ),"0")} -> ÖTELEME | V40: {=IFERROR(INDEX($A$4:$A$145,MATCH(0,COUNTIF($V$3:V39,$A$4:$A$145),0)),"0")} -> 0 | W40: 1 | X40: =U40*W40 -> #VALUE! | Y40: =W40*V40 -> 0
A41: RADYATÖR VANASI | B41: ECA | C41: 190 | D41: =IFERROR(IF(AND(LEN(A41)=0,LEN(B41)=0),"",IF(LEN(B41)=0,A41,A41&"-"&B41)),"") -> RADYATÖR VANASI-ECA | U41: {=IFERROR(INDEX($B$4:$B$145, SMALL(IF((LEN($B$4:$B$145)<>0),ROW($B$4:$B$145)-ROW($B$3),"0"),ROW(B24)-ROW($B$3)) ),"0")} -> HAZIR | V41: {=IFERROR(INDEX($A$4:$A$145,MATCH(0,COUNTIF($V$3:V40,$A$4:$A$145),0)),"0")} -> 0 | W41: 1 | X41: =U41*W41 -> #VALUE! | Y41: =W41*V41 -> 0
...

Sheet Sheet1
C1: Ürünler | D1: TİPLERİ
A2: =OFFSET(INDEX(Sheet1!$C$2:$C$25,MATCH(#REF!,Sheet1!$C$2:$C$25,0)),,1,1,INDEX(Sheet1!$B$2:$B$25,MATCH(#REF!,Sheet1!$C$2:$C$25,0))) -> #REF! | B2: =IF(LEN(C2)=0,"",COUNTA(D2:KI2)) -> 3 | C2: BACA DİRSEĞİ | D2: 90 DERECE | E2: 45 DERECE | F2: YOK
A3: =OFFSET(INDEX(Sheet1!$C$2:$C$25,MATCH(B1,Sheet1!$C$2:$C$25,0)),,1,1,INDEX(Sheet1!$B$2:$B$25,MATCH(B1,Sheet1!$C$2:$C$25,0))) -> #N/A | B3: =IF(LEN(C3)=0,"",COUNTA(D3:KI3)) -> 3 | C3: BACA UZATMASI | D3: 50 CM | E3: 1 METRE | F3: YOK
A4: =OFFSET(INDEX(Sheet1!$C$2:$C$25,MATCH(B2,Sheet1!$C$2:$C$25,0)),,1,1,INDEX(Sheet1!$B$2:$B$25,MATCH(B2,Sheet1!$C$2:$C$25,0))) -> #N/A | B4: =IF(LEN(C4)=0,"",COUNTA(D4:KI4)) -> 2 | C4: CAM MENFEZ | D4: YOK | E4: VAR
A5: =OFFSET(INDEX(Sheet1!$C$2:$C$25,MATCH(B3,Sheet1!$C$2:$C$25,0)),,1,1,INDEX(Sheet1!$B$2:$B$25,MATCH(B3,Sheet1!$C$2:$C$25,0))) -> #N/A | B5: =IF(LEN(C5)=0,"",COUNTA(D5:KI5)) -> 2 | C5: DOĞALGAZ TESİSATI | D5: ÇELİK_BORU | E5: ESNEK_BORU
A6: =OFFSET(INDEX(Sheet1!$C$2:$C$25,MATCH(B4,Sheet1!$C$2:$C$25,0)),,1,1,INDEX(Sheet1!$B$2:$B$25,MATCH(B4,Sheet1!$C$2:$C$25,0))) -> #N/A | B6: =IF(LEN(C6)=0,"",COUNTA(D6:KI6)) -> 2 | C6: ELEKTİRİK TESİSATI | D6: YOK | E6: VAR
A7: =OFFSET(INDEX(Sheet1!$C$2:$C$25,MATCH(B5,Sheet1!$C$2:$C$25,0)),,1,1,INDEX(Sheet1!$B$2:$B$25,MATCH(B5,Sheet1!$C$2:$C$25,0))) -> #N/A | B7: =IF(LEN(C7)=0,"",COUNTA(D7:KI7)) -> 2 | C7: EXTRA ISCILIK | D7: VAR | E7: YOK
A8: =OFFSET(INDEX(Sheet1!$C$2:$C$25,MATCH(B7,Sheet1!$C$2:$C$25,0)),,1,1,INDEX(Sheet1!$B$2:$B$25,MATCH(B7,Sheet1!$C$2:$C$25,0))) -> #N/A | B8: =IF(LEN(C8)=0,"",COUNTA(D8:KI8)) -> 2 | C8: HAVLUPAN | D8: KROM | E8: BEYAZ
A9: =OFFSET(INDEX(Sheet1!$C$2:$C$25,MATCH(#REF!,Sheet1!$C$2:$C$25,0)),,1,1,INDEX(Sheet1!$B$2:$B$25,MATCH(#REF!,Sheet1!$C$2:$C$25,0))) -> #REF! | B9: =IF(LEN(C9)=0,"",COUNTA(D9:KI9)) -> 3 | C9: İŞÇİLİK | D9: MONTAJ | E9: KOMPLE | F9: KOMBİ + GAZ
A10: =OFFSET(INDEX(Sheet1!$C$2:$C$25,MATCH(B8,Sheet1!$C$2:$C$25,0)),,1,1,INDEX(Sheet1!$B$2:$B$25,MATCH(B8,Sheet1!$C$2:$C$25,0))) -> #N/A | B10: =IF(LEN(C10)=0,"",COUNTA(D10:KI10)) -> 3 | C10: KALORİFER TESİSATI | D10: KOMPLE | E10: ÖTELEME | F10: HAZIR
A11: =OFFSET(INDEX(Sheet1!$C$2:$C$25,MATCH(B9,Sheet1!$C$2:$C$25,0)),,1,1,INDEX(Sheet1!$B$2:$B$25,MATCH(B9,Sheet1!$C$2:$C$25,0))) -> #N/A | B11: =IF(LEN(C11)=0,"",COUNTA(D11:KI11)) -> 12 | C11: KOMBİ | D11: BOSCH_CONDENCE1200İ_20kW | E11: BOSCH_CONDENCE2200İ_20kW | F11: BOSCH_CONDENCE1200İ_24kW | G11: ECA_CİTİUS_24kW | H11: ECA_PROTEUS_PREMİX_24kW | I11: ECA_CONFEO_PREMİX_24kW | J11: AİRFELL_MAESTRO_OPTİMUM_20kW | K11: AİRFELL_MAESTRO_OPTİMUM_23kW | AJ11: ECA_CİTİUS_24kW | AK11: ECA_CALORA_24kW | AL11: ECA_CONFEO_PREMİX_24kW | AM11: ECA_PROTEUS_PREMİX_24kW
A12: =OFFSET(INDEX(Sheet1!$C$2:$C$25,MATCH(B10,Sheet1!$C$2:$C$25,0)),,1,1,INDEX(Sheet1!$B$2:$B$25,MATCH(B10,Sheet1!$C$2:$C$25,0))) -> #N/A | B12: =IF(LEN(C12)=0,"",COUNTA(D12:KI12)) -> 2 | C12: KOMBİ DOLABI | D12: VAR | E12: YOK
A13: =OFFSET(INDEX(Sheet1!$C$2:$C$25,MATCH(B11,Sheet1!$C$2:$C$25,0)),,1,1,INDEX(Sheet1!$B$2:$B$25,MATCH(B11,Sheet1!$C$2:$C$25,0))) -> #N/A | B13: =IF(LEN(C13)=0,"",COUNTA(D13:KI13)) -> 4 | C13: ODA TERMOSTATI | D13: AİRFELL_KABLOSUZ_TERMOSTAT | E13: ECA_KABLOSUZ_TERMOSTAT | F13: BOSCH_KABLOSUZ_TERMOSTAT | G13: YOK
A14: =OFFSET(INDEX(Sheet1!$C$2:$C$25,MATCH(B12,Sheet1!$C$2:$C$25,0)),,1,1,INDEX(Sheet1!$B$2:$B$25,MATCH(B12,Sheet1!$C$2:$C$25,0))) -> #N/A | B14: =IF(LEN(C14)=0,"",COUNTA(D14:KI14)) -> 2 | C14: RADYATÖR | D14: ECA | E14: WARMHAUS
A15: =OFFSET(INDEX(Sheet1!$C$2:$C$25,MATCH(B13,Sheet1!$C$2:$C$25,0)),,1,1,INDEX(Sheet1!$B$2:$B$25,MATCH(B13,Sheet1!$C$2:$C$25,0))) -> #N/A | B15: =IF(LEN(C15)=0,"",COUNTA(D15:KI15)) -> 2 | C15: RADYATÖR VANASI | D15: KALDE | E15: ECA
A16: =OFFSET(INDEX(Sheet1!$C$2:$C$25,MATCH(B15,Sheet1!$C$2:$C$25,0)),,1,1,INDEX(Sheet1!$B$2:$B$25,MATCH(B15,Sheet1!$C$2:$C$25,0))) -> #N/A | B16: =IF(LEN(C16)=0,"",COUNTA(D16:KI16)) -> 2 | C16: FİRMA GİDERİ | D16: VAR | E16: YOK
A17: =OFFSET(INDEX(Sheet1!$C$2:$C$25,MATCH(#REF!,Sheet1!$C$2:$C$25,0)),,1,1,INDEX(Sheet1!$B$2:$B$25,MATCH(#REF!,Sheet1!$C$2:$C$25,0))) -> #REF! | B17: =IF(LEN(C17)=0,"",COUNTA(D17:KI17))
A18: =OFFSET(INDEX(Sheet1!$C$2:$C$25,MATCH(B16,Sheet1!$C$2:$C$25,0)),,1,1,INDEX(Sheet1!$B$2:$B$25,MATCH(B16,Sheet1!$C$2:$C$25,0))) -> #N/A | B18: =IF(LEN(C18)=0,"",COUNTA(D18:KI18))
A19: =OFFSET(INDEX(Sheet1!$C$2:$C$25,MATCH(B17,Sheet1!$C$2:$C$25,0)),,1,1,INDEX(Sheet1!$B$2:$B$25,MATCH(B17,Sheet1!$C$2:$C$25,0))) -> #N/A | B19: =IF(LEN(C19)=0,"",COUNTA(D19:KI19))
A20: =OFFSET(INDEX(Sheet1!$C$2:$C$25,MATCH(B18,Sheet1!$C$2:$C$25,0)),,1,1,INDEX(Sheet1!$B$2:$B$25,MATCH(B18,Sheet1!$C$2:$C$25,0))) -> #N/A | B20: =IF(LEN(C20)=0,"",COUNTA(D20:KI20))
A21: =OFFSET(INDEX(Sheet1!$C$2:$C$25,MATCH(B19,Sheet1!$C$2:$C$25,0)),,1,1,INDEX(Sheet1!$B$2:$B$25,MATCH(B19,Sheet1!$C$2:$C$25,0))) -> #N/A | B21: =IF(LEN(C21)=0,"",COUNTA(D21:KI21))
A22: =OFFSET(INDEX(Sheet1!$C$2:$C$25,MATCH(B20,Sheet1!$C$2:$C$25,0)),,1,1,INDEX(Sheet1!$B$2:$B$25,MATCH(B20,Sheet1!$C$2:$C$25,0))) -> #N/A | B22: =IF(LEN(C22)=0,"",COUNTA(D22:KI22))
A23: =OFFSET(INDEX(Sheet1!$C$2:$C$25,MATCH(B21,Sheet1!$C$2:$C$25,0)),,1,1,INDEX(Sheet1!$B$2:$B$25,MATCH(B21,Sheet1!$C$2:$C$25,0))) -> #N/A | B23: =IF(LEN(C23)=0,"",COUNTA(D23:KI23))
A24: =OFFSET(INDEX(Sheet1!$C$2:$C$25,MATCH(B22,Sheet1!$C$2:$C$25,0)),,1,1,INDEX(Sheet1!$B$2:$B$25,MATCH(B22,Sheet1!$C$2:$C$25,0))) -> #N/A | B24: =IF(LEN(C24)=0,"",COUNTA(D24:KI24))
A25: =OFFSET(INDEX(Sheet1!$C$2:$C$25,MATCH(B23,Sheet1!$C$2:$C$25,0)),,1,1,INDEX(Sheet1!$B$2:$B$25,MATCH(B23,Sheet1!$C$2:$C$25,0))) -> #N/A | B25: =IF(LEN(C25)=0,"",COUNTA(D25:KI25))
